---
title:  "[윤성우 열혈 C++ 프로그래밍] Chapter15_예외 처리(Exception Handing)"

categories:
  - Cpp
tags:
  - [Programming, Cpp]

toc: true
toc_sticky: true
 
date: 2023-06-05
last_modified_at: 2023-06-05
---
<br>

## 15-1 예외상황과 예외처리의 이해

**예외상황을 처리하지 않았을 때의 결과**

예외(Exception) : <u>프로그램 실행 도중에 발생</u>하는 예외적인 문제 상황
- C++은 이러한 예외적인 상황의 처리를 위한 문법을 별도로 제공
- C++에서 말하는 `예외`는 컴파일 시 발생하는 문법적인 에러는 예외의 범주에 포함하지 않음
- 문법적인 오류가 아닌, 프로그램의 논리에 맞지 않는 상황을 의미
  - ex)나이를 입력 받는데 0보다 작은 값이 입력되었다, 나눗셈을 하는데 제수로 0이 입력되었다...

**if문을 이용한 예외의 처리**

```c++
int num1, num2;
cin >> num1 >> num2;                // 예외 발생 위치

if(num2 == 0){                      // 예외 발견 위치
    cout << "제수는 0이 될 수 없다." << endl;   // 예외 처리 위치
    cout << "프로그램을 다시 실행." << endl;    // 예외 처리 위치
}
else{
    cout << num1/num2 << endl;
    cout << num1%num2 << endl;
}
```

- 예외 발생 위치와 발견 위치는 다를 수 있다.
- 이 방법의 단점 : 예외처리 코드와 프로그램의 흐름을 구성하는 코드의 구분이 어려움

## 15-2 C++의 예외처리 메커니즘

C++은 구조적으로 예외를 처리할 수 있는 메커니즘을 제공
이 메커니즘을 이요하면, 코드의 가독성과 유지보수성을 높일 수 있다.(예외 처리를 프로그램의 일반적인 흐름에서 독립시키는 것이 가능)

**C++의 예외처리 메커니즘 이해 : try와 catch 그리고 throw의 이해**

예외처리 메커니즘의 세가지 키워드
1. **try**      예외 발견
2. **carch**    예외 잡기
3. **throw**    예외 던지기기

**try 블록**

- 예외발생에 대한 검사의 범위를 지정
- try 블록 내에서 예외가 발생하면, C++ 예외처리 메커니즘에 의해 처리

```c++
try{
    // 예외발생 예상지역
}
```

**catch 블록**

- try 블록에서 발생한 예외를 처리하는 코드 영역
- 형태가 반환형 없는 함수와 유사

```c++
catch(처리할 예외의 종류 명시){
    // 예외처리 코드의 삽입
}
```

**try블록과 catch블록**

- catch블록은 try블록 뒤에 이어서 등장(사실 둘은 하나의 문장)
- 중간에 다른 문장이 오면 안 됨 // 컴파일 에러!!

- *try블록 내에서 발생하는 예외는 이어서 등장하는 catch블록에 의해 처리된다.*

**throw**

- 키워드 throw는 예외가 발생했음을 알리는 문장의 구성

```c++
throw expn;
```

- expn
  - 변수, 상수, 객체 등 표현 가능한 모든 데이터
  - 예외상황에 대한 정보를 담은, 의미있는 데이터
  - 그냥 '예외'라고 표현하기도 함
- 위 문장을 만나면 C++의 예외처리 메커니즘 동작, 일반적 프로그램의 흐름과 다른 예외처리의 흐름 시작됨

*<u>throw에 의해 던져진 '예외 데이터'는 '예외 데이터'를 감싸는 try블록에 의해서 감지가 되어 catch블록에 의해 처리된다.</u>*

**예외처리 메커니즘의 적용**

```c++
int num1, num2; 
cin >> num1 >> num2;

try{
    if(num2 == 0)
        throw num2;
    cout << num1/num2 << endl;
    cout << num1%num2 << endl;
}
catch(int expn){
    cout << "제수는 " << expn << "이 될 수 없다." << endl;
    cout << "프로그램 다시 실행" << endl;
}
```

- 예외상황이 발생하면 `throw num2;` 문장이 실행되어 예외데이터 num2의 값이 catch블록에 전달
- 예외가 발생한 지점 이후를 실행하는 것이 아니라, catch 블록의 이후가 실행됨
- 예외가 발생한 지점 이후의 나머지 try 영역은 건너뛴다
- throw절에 의해 던져진 예외 데이터 자료형과 catch 블록의 매개변수 자료형은 일치해야 함

**try 블록을 묶는 기준**

예외가 발생할만한 영역 + 그와 관련된 모든 문장을 묵어서 하나의 '일(work)' 단위로 구성

## 15-3 Stack Unwinding(스택 풀기)

throw절에 의해서 예외가 발생했지만 처리하지 않으면 어떻게 될까?

**예외의 전달**

MyFunc 함수를 호출했는데 그 안에서 throw절이 실행되며 예외가 발생했다. 그러나 이 함수 내에는 try~catch문이 존재하지 않는다. 그렇다면 발생한 예외는 어떻게 처리되는가?
- 예외처리에 대한 책임은 <u>MyFunc를 호출한 영역</u>으로 넘어가게 됨

```c++
void Divide(int num1, int num2){
    if(num2 == 0)
        throw num2;
}

try{
    Divide(num1, num2); // 예외 데이터 전달
}
catch(int expn){
    ...
}
```

- Divide 함수 내에서 예외가 발생했을 때 이 위치를 감싸는 try~catch문은 존재하지 않는다.
- 이런 경우 Divide 함수를 호출한 위치로 예외 데이터가 전달, 예외처리 책임
- 예외 데이터의 전달은 함수호출에 따른 값의 반환과 형태가 유사

- 이러한 특성은 예외 발생 위치와 예외 처리 위치가 달라야할 때 유용

**예외상황이 발생한 위치와 예외상황을 처리해야 하는 위치가 다른 경우**

대부분의 경우 예외 발생위치와 처리위치는 다르다.

```c++
int StoI(char * str){
    for(int i = 0; i < len; i++){
        if(str[i]<'0' || str[i]>'9')
            throw str[i];
        num += (int)(pow((double)10, (len-1)-i*(str[i]+7-'7')));
    }
    return num;
}

int main(){
    while(1){
        try{
            cout << str1 << " + " << str2 << " = " << StoI(str1)+StoI(str2) << endl;
            break;
        }
        catch(char ch){
            ...
        }
    }
}
```

- StoI 함수에 대한 예외처리는 함수를 호출하는 대상 및 상황에 따라서 달라지기 때문에 예외 처리를 StoI 함수를 호출한 영역으로 넘기는 것이 타당
- 예외발생 시 실행되는 catch 블록에 break문 존재하지 않음, 예외 발생 시 반복문 영역 재실행 이것이 이 예제의 예외 처리 방법
- 함수 호출 영역으로 예외 데이터를 전달하면 해당 함수는 더 이상 실행되지 않고 종료

**스택 풀기(Stack Unwinding)**

스택 풀기 : 함수를 호출한 영역으로 예외 데이터가 전달되는 현상

```c++
int main(){
    try{
        SimpleFuncOne();
    }
    catch(int expn){
        ...
    }
}

void SimpleFuncOne(){
    SimpleFuncTwo();
}

void SimpleFuncTwo(){
    SimpleFuncThree();
}

void SimpleFuncThree(){
    throw -1;
}
```

- 함수호출 순서 : main -> SimpleFuncOne -> SimpleFuncTwo -> SimplefuncThree
- 예외 데이터가 호출된 함수의 역순으로 전달
- 예외는 SimpleFuncThree 함수에서 발생했지만, 처리는 main 함수에서 이뤄짐
- 예외 데이터를 전달한 함수는 종료되고 스택이 반환됨, 그래서 예외 데이터의 전달을 스택 풀기라고 한다.

만약 main함수의 try~catch문을 삭제하면?
-> terminate 함수(프로그램을 종료시키는 함수)가 호출되며 프로그램 종료
- 그러니 시스템 오류, 더 이상 프로그램의 실행이 불가능한 예외상황이 아니라면 프로그래머가 예외상황을 처리해야 함

**자료형이 일치하지 않아도 예외 데이터는 전달됩니다.**

```c++
int Simplefunc(){
    ...
    try{
        if(...)
            throw -1;
        catch(char expn){ ... }
    }
}
```

- 자료형의 불일치로 예외는 처리되지 않고, 함수를 호출한 영역으로 예외 데이터가 전달된다.

**하나의 try 블록과 다수의 catch 블록**

하나의 try 블록 내에서 다른 유형의 예외상황이 둘 이상 발생할 경우,  각각의 예외 데이터의 자료형이 다를 수 있기 때문에 <u>catch 블록은 둘 이상이 될 수 있다</u>.

```c++
int StoI(char * str){
    if(len!=0 && str[0]='0')
        throw 0;

    for(int i = 0; i < len; i++){
        if(str[i]<'0' || str[i]>'9')
            throw str[i];
        num += (int)(pow((double)10, (len-1)-i*(str[i]+7-'7')));
    }
}

int main(){
    while(1){
        try{
            ...
            break;
        }
        catch(char ch){
            ...
        }
        catch(int expn){
            ...
        }
    }
}
```

**전달되는 예외의 명시**

함수 내에서 발생할 수 잇는 예외의 종류도 함수의 특징으로 간주
- 특정 함수의 호출을 위해서는 함수의 이름, 매개변수 선언, 반환형 정보 + 함수 내에서 전달될 수 있는 예외의 종류(예외 데이터 자료형)과 그 상황도 알아야 함
- 그래야 함수 호출 문장을 감싸는 적절한 try~catch블록 구성
- 따라서 함수 정의 시 예외의 종류를 같이 명시해 주는 것이 좋다.

```c++
int ThrowFunc(int num) throw (int, char){
    ...
}
```

- int형 예외 데이터와 char형 예외 데이터가 전달될 수 있다.

```c++
try{
    ...
    ThrowFunc(20);
}
catch(int expn){...}
catch(char expn){...}
```

- 함수의 원형 선언을 보고 위 형태의 함수 호출문을 구성

함수에 선언된 것 이외의 예외 데이터가 전달되었다는 것은 프로그래머의 실수 혹은 예상치 못했던 예외 발생에 대비가 안 된 것, 따라서 프로그램을 종료시켜 문제의 원일을 찾고 발생 가능한 예외의 유형을 점검하도록 유도하는 것이 바람직

```c++
int Simplefunc() throw(){
    ...
}
```

- 어떠한 예외도 전달하지 않는다는 의미
- 위 함수가 예외를 전달한다면 프로그램 종료

참고) unexpected 함수
함수의 선언에 명시되지 않은 예외가 전달될 경우, unexpected 함수가 호출되며, 이 함수의 기능은 프로그램 종료(terminate 함수의 호출)이다.

